<?xml version="1.0" encoding="utf-8"?>
<!-- =================================================================================== -->
<!-- |    This document was autogenerated by xacro from jaka_with_cam.urdf.xacro       | -->
<!-- |    EDITING THIS FILE BY HAND IS NOT RECOMMENDED                                 | -->
<!-- =================================================================================== -->
<robot name="jaka_with_cam">
  <!-- <link name="world"/>
<joint name="fixed" type="fixed">
  <parent link="world"/>
  <child link="cam_base_link"/>
  </joint> -->
  <link name="cam_base_link">
    <inertial>
      <origin rpy="0 0 0" xyz="0.0080061 -0.0015244 0.027175"/>
      <mass value="0.071566"/>
      <inertia ixx="1.1637E-05" ixy="1.1941E-15" ixz="1.7823E-09" iyy="1.8408E-05" iyz="4.1144E-07" izz="1.6521E-05"/>
    </inertial>
    <visual>
      <origin rpy="0 0 0" xyz="0 0 0"/>
      <geometry>
        <mesh filename="package://camhead/meshes/cam_base_link.STL"/>
      </geometry>
      <material name="">
        <color rgba="1 1 1 1"/>
      </material>
    </visual>
    <collision>
      <origin rpy="0 0 0" xyz="0 0 0"/>
      <geometry>
        <mesh filename="package://camhead/meshes/cam_base_link.STL"/>
      </geometry>
    </collision>
  </link>
  <link name="cam_link_1">
    <inertial>
      <origin rpy="0 0 0" xyz="0.00051383 -0.0075553 -0.0031082"/>
      <mass value="0.063261"/>
      <inertia ixx="8.7344E-06" ixy="1.7823E-09" ixz="-1.4423E-14" iyy="1.0704E-05" iyz="-4.1144E-07" izz="1.5531E-05"/>
    </inertial>
    <visual>
      <origin rpy="0 0 0" xyz="0 0 0"/>
      <geometry>
        <mesh filename="package://camhead/meshes/cam_link_1.STL"/>
      </geometry>
      <material name="">
        <color rgba="0.89412 0.91373 0.92941 1"/>
      </material>
    </visual>
    <collision>
      <origin rpy="0 0 0" xyz="0 0 0"/>
      <geometry>
        <mesh filename="package://camhead/meshes/cam_link_1.STL"/>
      </geometry>
    </collision>
  </link>
  <joint name="cam_joint_1" type="continuous">
    <origin rpy="0 0 0" xyz="0.0005 0.0001317 0.077"/>
    <parent link="cam_base_link"/>
    <child link="cam_link_1"/>
    <axis xyz="0 0 1"/>
    <limit effort="1000" lower="-3.14159265358" upper="3.14159265358" velocity="0.5"/>
  </joint>
  <transmission name="cam_joint_1_trans">
    <type>transmission_interface/SimpleTransmission</type>
    <actuator name="cam_joint_1_motor">
      <mechanicalReduction>1</mechanicalReduction>
    </actuator>
    <joint name="cam_joint_1">
      <hardwareInterface>hardware_interface/PositionJointInterface</hardwareInterface>
    </joint>
  </transmission>
  <link name="cam_link_2">
    <inertial>
      <origin rpy="0 0 0" xyz="-0.027603 4.6404E-17 0.016075"/>
      <mass value="0.029496"/>
      <inertia ixx="1.5198E-05" ixy="1.4672E-20" ixz="-5.571E-20" iyy="2.2438E-05" iyz="1.5789E-21" izz="9.8551E-06"/>
    </inertial>
    <visual>
      <origin rpy="0 0 0" xyz="0 0 0"/>
      <geometry>
        <mesh filename="package://camhead/meshes/cam_link_2.STL"/>
      </geometry>
      <material name="">
        <color rgba="0.75294 0.75294 0.75294 1"/>
      </material>
    </visual>
    <collision>
      <origin rpy="0 0 0" xyz="0 0 0"/>
      <geometry>
        <mesh filename="package://camhead/meshes/cam_link_2.STL"/>
      </geometry>
    </collision>
  </link>
  <joint name="cam_joint_2" type="continuous">
    <origin rpy="1.5708 1.5708 0" xyz="0.01 0 0"/>
    <parent link="cam_link_1"/>
    <child link="cam_link_2"/>
    <axis xyz="0 0 -1"/>
    <limit effort="1000" lower="-3.14159265358" upper="3.14159265358" velocity="0.5"/>
  </joint>
  <transmission name="cam_joint_2_trans">
    <type>transmission_interface/SimpleTransmission</type>
    <actuator name="cam_joint_2_motor">
      <mechanicalReduction>1</mechanicalReduction>
    </actuator>
    <joint name="cam_joint_2">
      <hardwareInterface>hardware_interface/PositionJointInterface</hardwareInterface>
    </joint>
  </transmission>
  <!-- <link
    name="rgbd_link">
    <inertial>
      <origin
        xyz="0.00097855 1.1266E-05 0.012138"
        rpy="0 0 0" />
      <mass
        value="0.10791" />
      <inertia
        ixx="7.1255E-05"
        ixy="-1.7847E-08"
        ixz="4.9298E-08"
        iyy="7.71E-06"
        iyz="2.4825E-10"
        izz="7.0257E-05" />
    </inertial>
    <visual>
      <origin
        xyz="0 0 0"
        rpy="0 0 0" />
      <geometry>
        <mesh
          filename="package://camhead/meshes/rgbd_link.STL" />
      </geometry>
      <material
        name="">
        <color
          rgba="0.89804 0.91765 0.92941 1" />
      </material>
    </visual>
    <collision>
      <origin
        xyz="0 0 0"
        rpy="0 0 0" />
      <geometry>
        <mesh
          filename="package://camhead/meshes/rgbd_link.STL" />
      </geometry>
    </collision>
  </link>
  <joint
    name="rgbd_joint"
    type="fixed">
    <origin
      xyz="-0.064577 -0.012274 0.0096665"
      rpy="1.5708 0 3.1416" />
    <parent
      link="cam_link_2" />
    <child
      link="rgbd_link" />
    <axis
      xyz="0 0 0" />
  </joint> -->
  <material name="camera_aluminum">
    <color rgba="0.5 0.5 0.5 1"/>
  </material>
  <!-- camera body, with origin at bottom screw mount -->
  <joint name="camera_joint" type="fixed">
    <origin rpy="1.5708 0 3.1416" xyz="-0.064577 -0.012274 0.0096665"/>
    <parent link="cam_link_2"/>
    <child link="camera_bottom_screw_frame"/>
  </joint>
  <link name="camera_bottom_screw_frame"/>
  <joint name="camera_link_joint" type="fixed">
    <origin rpy="0 0 0" xyz="0 0.0175 0.0125"/>
    <parent link="camera_bottom_screw_frame"/>
    <child link="camera_link"/>
  </joint>
  <link name="camera_link">
    <visual>
      <origin rpy="1.57079632679 0 1.57079632679" xyz="0.0149 -0.0175 0"/>
      <geometry>
        <!-- <box size="${d435_cam_width} ${d435_cam_height} ${d435_cam_depth}"/> -->
        <mesh filename="package://realsense2_description/meshes/d435.dae"/>
        <!--<mesh filename="package://realsense2_description/meshes/d435/d435.dae" />-->
      </geometry>
      <material name="camera_aluminum"/>
    </visual>
    <collision>
      <origin rpy="0 0 0" xyz="0 -0.0175 0"/>
      <geometry>
        <box size="0.02505 0.09 0.025"/>
      </geometry>
    </collision>
    <inertial>
      <!-- The following are not reliable values, and should not be used for modeling -->
      <mass value="0.00791"/>
      <origin xyz="0.00097855 1.1266E-05 0.012138"/>
      <inertia ixx="7.1255E-05" ixy="-1.7847E-08" ixz="4.9298E-08" iyy="7.71E-06" iyz="2.4825E-10" izz="7.0257E-05"/>
    </inertial>
  </link>
  <!-- camera depth joints and links -->
  <joint name="camera_depth_joint" type="fixed">
    <origin rpy="0 0 0" xyz="0 0 0"/>
    <parent link="camera_link"/>
    <child link="camera_depth_frame"/>
  </joint>
  <link name="camera_depth_frame"/>
  <joint name="camera_depth_optical_joint" type="fixed">
    <origin rpy="-1.57079632679 0 -1.57079632679" xyz="0 0 0"/>
    <parent link="camera_depth_frame"/>
    <child link="camera_depth_optical_frame"/>
  </joint>
  <link name="camera_depth_optical_frame"/>
  <!-- camera left IR joints and links -->
  <joint name="camera_left_ir_joint" type="fixed">
    <origin rpy="0 0 0" xyz="0 0.0 0"/>
    <parent link="camera_depth_frame"/>
    <child link="camera_left_ir_frame"/>
  </joint>
  <link name="camera_left_ir_frame"/>
  <joint name="camera_left_ir_optical_joint" type="fixed">
    <origin rpy="-1.57079632679 0 -1.57079632679" xyz="0 0 0"/>
    <parent link="camera_left_ir_frame"/>
    <child link="camera_left_ir_optical_frame"/>
  </joint>
  <link name="camera_left_ir_optical_frame"/>
  <!-- camera right IR joints and links -->
  <joint name="camera_right_ir_joint" type="fixed">
    <origin rpy="0 0 0" xyz="0 -0.05 0"/>
    <parent link="camera_depth_frame"/>
    <child link="camera_right_ir_frame"/>
  </joint>
  <link name="camera_right_ir_frame"/>
  <joint name="camera_right_ir_optical_joint" type="fixed">
    <origin rpy="-1.57079632679 0 -1.57079632679" xyz="0 0 0"/>
    <parent link="camera_right_ir_frame"/>
    <child link="camera_right_ir_optical_frame"/>
  </joint>
  <link name="camera_right_ir_optical_frame"/>
  <!-- camera color joints and links -->
  <joint name="camera_color_joint" type="fixed">
    <origin rpy="0 0 0" xyz="0 0.015 0"/>
    <parent link="camera_depth_frame"/>
    <child link="camera_color_frame"/>
  </joint>
  <link name="camera_color_frame"/>
  <joint name="camera_color_optical_joint" type="fixed">
    <origin rpy="-1.57079632679 0 -1.57079632679" xyz="0 0 0"/>
    <parent link="camera_color_frame"/>
    <child link="camera_color_optical_frame"/>
  </joint>
  <link name="camera_color_optical_frame"/>
  <gazebo reference="camera_link">
    <self_collide>0</self_collide>
    <enable_wind>0</enable_wind>
    <kinematic>0</kinematic>
    <gravity>1</gravity>
    <!--<mu>1</mu>-->
    <mu2>1</mu2>
    <fdir1>0 0 0</fdir1>
    <!--<slip1>0</slip1>
      <slip2>0</slip2>-->
    <kp>1e+13</kp>
    <kd>1</kd>
    <!--<max_vel>0.01</max_vel>
      <min_depth>0</min_depth>-->
    <sensor name="cameracolor" type="camera">
      <camera name="camera">
        <horizontal_fov>1.21125850088</horizontal_fov>
        <image>
          <width>640</width>
          <height>480</height>
          <format>RGB_INT8</format>
        </image>
        <clip>
          <near>0.1</near>
          <far>100</far>
        </clip>
        <noise>
          <type>gaussian</type>
          <mean>0.0</mean>
          <stddev>0.007</stddev>
        </noise>
      </camera>
      <always_on>1</always_on>
      <update_rate>30</update_rate>
      <visualize>1</visualize>
    </sensor>
    <sensor name="cameraired1" type="camera">
      <camera name="camera">
        <horizontal_fov>1.4870205227</horizontal_fov>
        <image>
          <width>1280</width>
          <height>720</height>
          <format>L_INT8</format>
        </image>
        <clip>
          <near>0.1</near>
          <far>100</far>
        </clip>
        <noise>
          <type>gaussian</type>
          <mean>0.0</mean>
          <stddev>0.05</stddev>
        </noise>
      </camera>
      <always_on>1</always_on>
      <update_rate>90</update_rate>
      <visualize>0</visualize>
    </sensor>
    <sensor name="cameraired2" type="camera">
      <camera name="camera">
        <horizontal_fov>1.4870205227</horizontal_fov>
        <image>
          <width>1280</width>
          <height>720</height>
          <format>L_INT8</format>
        </image>
        <clip>
          <near>0.1</near>
          <far>100</far>
        </clip>
        <noise>
          <type>gaussian</type>
          <mean>0.0</mean>
          <stddev>0.05</stddev>
        </noise>
      </camera>
      <always_on>1</always_on>
      <update_rate>90</update_rate>
      <visualize>0</visualize>
    </sensor>
    <sensor name="cameradepth" type="depth">
      <camera name="camera">
        <horizontal_fov>1.4870205227</horizontal_fov>
        <image>
          <width>1280</width>
          <height>720</height>
        </image>
        <clip>
          <near>0.1</near>
          <far>100</far>
        </clip>
        <noise>
          <type>gaussian</type>
          <mean>0.0</mean>
          <stddev>0.100</stddev>
        </noise>
      </camera>
      <always_on>1</always_on>
      <update_rate>90</update_rate>
      <visualize>0</visualize>
    </sensor>
  </gazebo>
  <gazebo>
    <plugin filename="librealsense_gazebo_plugin.so" name="camera">
      <prefix>camera</prefix>
      <depthUpdateRate>30.0</depthUpdateRate>
      <colorUpdateRate>30.0</colorUpdateRate>
      <infraredUpdateRate>30.0</infraredUpdateRate>
      <depthTopicName>depth/image_raw</depthTopicName>
      <depthCameraInfoTopicName>depth/camera_info</depthCameraInfoTopicName>
      <colorTopicName>color/image_raw</colorTopicName>
      <colorCameraInfoTopicName>color/camera_info</colorCameraInfoTopicName>
      <infrared1TopicName>infra1/image_raw</infrared1TopicName>
      <infrared1CameraInfoTopicName>infra1/camera_info</infrared1CameraInfoTopicName>
      <infrared2TopicName>infra2/image_raw</infrared2TopicName>
      <infrared2CameraInfoTopicName>infra2/camera_info</infrared2CameraInfoTopicName>
      <colorOpticalframeName>camera_color_optical_frame</colorOpticalframeName>
      <depthOpticalframeName>camera_depth_optical_frame</depthOpticalframeName>
      <infrared1OpticalframeName>camera_left_ir_optical_frame</infrared1OpticalframeName>
      <infrared2OpticalframeName>camera_right_ir_optical_frame</infrared2OpticalframeName>
      <rangeMinDepth>0.2</rangeMinDepth>
      <rangeMaxDepth>10.0</rangeMaxDepth>
      <pointCloud>True</pointCloud>
      <pointCloudTopicName>depth/color/points</pointCloudTopicName>
      <pointCloudCutoff>0.25</pointCloudCutoff>
      <pointCloudCutoffMax>9.0</pointCloudCutoffMax>
    </plugin>
  </gazebo>
  <gazebo>
    <plugin filename="libgazebo_ros_control.so" name="gazebo_ros_control">
      <robotNamespace>/camhead</robotNamespace>
    </plugin>
  </gazebo>
  <material name="blue">
    <color rgba="0 0 0.8 1"/>
  </material>
  <material name="black">
    <color rgba="0 0 0 1"/>
  </material>
  <material name="white">
    <color rgba="1 1 1 1"/>
  </material>
  <!-- <link name="world">
      <origin rpy="0 0 0" xyz="0 0 -0.2"/>
  </link>
  <joint name="fixed" type="fixed">
 <origin rpy="0 0 0" xyz="0 0 -0.8"/>
    <parent link="world"/>
    <child link="base_link"/>
  </joint> -->
  <joint name="bottom_joint" type="fixed">
    <origin rpy="0 0 0" xyz="0 0 0"/>
    <parent link="base_link"/>
    <child link="bottom_link"/>
  </joint>
  <link name="bottom_link">
    <!--visual>
      <origin xyz=" 0 0 -0.04"  rpy="0 0 0"/>
      <geometry>

               <box size="1 1 0.02" />

      </geometry>
      <material name="Brown" />
    </visual>

    <collision>
      <origin xyz=" 0 0 -0.04"  rpy="0 0 0"/>
      <geometry>
               <box size="1 1 0.02" />
      </geometry>
      </collision>-->
    <inertial>
      <mass value="5"/>
      <inertia ixx="0.2" ixy="0.0" ixz="0.0" iyy="0.2" iyz="0.0" izz="0.1"/>
    </inertial>
  </link>
  <link name="base_link">
    <visual>
      <!--origin rpy="0 ${pi / 2} 0" xyz="0 0 0.0198"/>-->
      <origin rpy="0 0 0" xyz="0 0 -0.0005"/>
      <geometry>
        <mesh filename="package://Zu7/mesh/p11.dae"/>
      </geometry>
      <material name="white"/>
    </visual>
    <collision>
      <geometry>
        <mesh filename="package://Zu7/mesh/p11.dae"/>
      </geometry>
      <origin rpy="0 0 0" xyz="0 0 -0.0005"/>
    </collision>
    <!--inertial>
      <mass value="5"/>
      <inertia ixx="0.2" ixy="0.0" ixz="0.0" iyy="0.2" iyz="0.0" izz="0.1"/>
    </inertial-->
  </link>
  <link name="link_1">
    <visual>
      <geometry>
        <mesh filename="package://Zu7/mesh/p22.dae"/>
      </geometry>
      <material name="white"/>
      <!--origin rpy=" ${pi/2.0}  0  ${pi/2.0}" xyz="0 0 0"/>-->
      <origin rpy=" 0  0  0" xyz="0 0 0"/>
    </visual>
    <collision>
      <geometry>
        <mesh filename="package://Zu7/mesh/p22.dae"/>
      </geometry>
      <origin rpy=" 0  0  0" xyz="0 0 0"/>
    </collision>
    <inertial>
      <mass value="8"/>
      <inertia ixx="0.3" ixy="0.0" ixz="0.0" iyy="0.3" iyz="0.0" izz="0.2"/>
    </inertial>
  </link>
  <joint name="joint_1" type="revolute">
    <axis xyz="0 0 1"/>
    <limit effort="1000" lower="-3.14159265358" upper="3.14159265358" velocity="0.5"/>
    <origin rpy="0 0 0" xyz="0 0 0.114"/>
    <parent link="base_link"/>
    <child link="link_1"/>
  </joint>
  <transmission name="joint_1_trans">
    <type>transmission_interface/SimpleTransmission</type>
    <actuator name="$joint_1_motor">
      <mechanicalReduction>1</mechanicalReduction>
    </actuator>
    <joint name="joint_1">
      <hardwareInterface>hardware_interface/PositionJointInterface</hardwareInterface>
    </joint>
  </transmission>
  <link name="link_2">
    <visual>
      <geometry>
        <mesh filename="package://Zu7/mesh/p35.dae"/>
      </geometry>
      <!--origin rpy="${pi/2.0}  ${pi} ${pi/2.0}" xyz="-0.1595 0 -0.115"/>-->
      <material name="white"/>
      <origin rpy="1.57079632679 3.14159265358 1.57079632679" xyz="0 0 0.005 "/>
    </visual>
    <collision>
      <geometry>
        <mesh filename="package://Zu7/mesh/p35.dae"/>
      </geometry>
      <origin rpy="1.57079632679 3.14159265358 1.57079632679" xyz="0 0 0.005 "/>
    </collision>
    <inertial>
      <mass value="6"/>
      <inertia ixx="0.25" ixy="0.0" ixz="0.0" iyy="0.25" iyz="0.0" izz="0.15"/>
    </inertial>
  </link>
  <joint name="joint_2" type="revolute">
    <axis xyz="0 0 1"/>
    <limit effort="1000" lower="-3.14159265358" upper="3.14159265358" velocity="0.5"/>
    <origin rpy="1.57079632679 0 0" xyz="0 0 0"/>
    <parent link="link_1"/>
    <child link="link_2"/>
  </joint>
  <transmission name="joint_2_trans">
    <type>transmission_interface/SimpleTransmission</type>
    <actuator name="$joint_2_motor">
      <mechanicalReduction>1</mechanicalReduction>
    </actuator>
    <joint name="joint_2">
      <hardwareInterface>hardware_interface/PositionJointInterface</hardwareInterface>
    </joint>
  </transmission>
  <link name="link_3">
    <visual>
      <geometry>
        <mesh filename="package://Zu7/mesh/p44.dae"/>
      </geometry>
      <material name="white"/>
      <origin rpy="-1.57079632679 0 -1.57079632679" xyz="0.303 0 -0.013"/>
    </visual>
    <collision>
      <geometry>
        <mesh filename="package://Zu7/mesh/p44.dae"/>
      </geometry>
      <origin rpy="-1.57079632679 0 -1.57079632679" xyz="0.303 0 -0.013"/>
    </collision>
    <inertial>
      <mass value="8"/>
      <inertia ixx="0.3" ixy="0.0" ixz="0.0" iyy="0.3" iyz="0.0" izz="0.2"/>
    </inertial>
  </link>
  <joint name="joint_3" type="revolute">
    <axis xyz="0 0 1"/>
    <limit effort="1000" lower="-3.14159265358" upper="3.14159265358" velocity="0.5"/>
    <origin rpy="0 0 0" xyz="0.353 0 0"/>
    <parent link="link_2"/>
    <child link="link_3"/>
  </joint>
  <transmission name="joint_3_trans">
    <type>transmission_interface/SimpleTransmission</type>
    <actuator name="joint_3_motor">
      <mechanicalReduction>1</mechanicalReduction>
    </actuator>
    <joint name="joint_3">
      <hardwareInterface>hardware_interface/PositionJointInterface</hardwareInterface>
    </joint>
  </transmission>
  <link name="link_4">
    <visual>
      <geometry>
        <mesh filename="package://Zu7/mesh/p55.dae"/>
      </geometry>
      <origin rpy="1.57079632679 0 1.57079632679" xyz="0.00 0 0.00"/>
      <material name="white"/>
    </visual>
    <collision>
      <geometry>
        <mesh filename="package://Zu7/mesh/p55.dae"/>
      </geometry>
      <origin rpy="1.57079632679 0 1.57079632679" xyz="0.00 0 0.00"/>
    </collision>
    <inertial>
      <mass value="5"/>
      <inertia ixx="0.2" ixy="0.0" ixz="0.0" iyy="0.2" iyz="0.0" izz="0.15"/>
    </inertial>
  </link>
  <joint name="joint_4" type="revolute">
    <axis xyz="0 0 1"/>
    <limit effort="1000" lower="-3.14159265358" upper="3.14159265358" velocity="0.5"/>
    <origin rpy="0 0 0" xyz="0.303 0 -0.1155"/>
    <parent link="link_3"/>
    <child link="link_4"/>
  </joint>
  <transmission name="joint_4_trans">
    <type>transmission_interface/SimpleTransmission</type>
    <actuator name="joint_4_motor">
      <mechanicalReduction>1</mechanicalReduction>
    </actuator>
    <joint name="joint_4">
      <hardwareInterface>hardware_interface/PositionJointInterface</hardwareInterface>
    </joint>
  </transmission>
  <link name="link_5">
    <visual>
      <geometry>
        <mesh filename="package://Zu7/mesh/p66.dae"/>
      </geometry>
      <origin rpy="3.14159265358 0 -1.57079632679" xyz="0 0 0"/>
      <material name="white"/>
    </visual>
    <collision>
      <geometry>
        <mesh filename="package://Zu7/mesh/p66.dae"/>
      </geometry>
      <origin rpy="3.14159265358 0 -1.57079632679" xyz="0 0 0"/>
    </collision>
    <inertial>
      <mass value="4"/>
      <inertia ixx="0.1" ixy="0.0" ixz="0.0" iyy="0.1" iyz="0.0" izz="0.07"/>
    </inertial>
  </link>
  <joint name="joint_5" type="revolute">
    <axis xyz="0 0 1"/>
    <limit effort="1000" lower="-3.14159265358" upper="3.14159265358" velocity="0.5"/>
    <origin rpy="1.57079632679 0 0" xyz="0 -0.1025 0"/>
    <parent link="link_4"/>
    <child link="link_5"/>
  </joint>
  <transmission name="joint_5_trans">
    <type>transmission_interface/SimpleTransmission</type>
    <actuator name="joint_5_motor">
      <mechanicalReduction>1</mechanicalReduction>
    </actuator>
    <joint name="joint_5">
      <hardwareInterface>hardware_interface/PositionJointInterface</hardwareInterface>
    </joint>
  </transmission>
  <link name="link_6">
    <visual>
      <geometry>
        <mesh filename="package://Zu7/mesh/p77.dae"/>
      </geometry>
      <origin rpy="0 -1.57079632679  0" xyz="0 0 -0.0335"/>
    </visual>
    <collision>
      <geometry>
        <mesh filename="package://Zu7/mesh/p77.dae"/>
      </geometry>
      <origin rpy="0 -1.57079632679  0" xyz="0 0 -0.0335"/>
    </collision>
    <inertial>
      <mass value="2"/>
      <inertia ixx="0.07" ixy="0.0" ixz="0.0" iyy="0.07" iyz="0.0" izz="0.04"/>
    </inertial>
  </link>
  <joint name="joint_6" type="revolute">
    <axis xyz="0 0 1"/>
    <limit effort="1000" lower="-3.14159265358" upper="3.14159265358" velocity="0.5"/>
    <origin rpy="-1.57079632679 0 0" xyz="0 0.093 0"/>
    <parent link="link_5"/>
    <child link="link_6"/>
  </joint>
  <transmission name="joint_6_trans">
    <type>transmission_interface/SimpleTransmission</type>
    <actuator name="joint_6_motor">
      <mechanicalReduction>1</mechanicalReduction>
    </actuator>
    <joint name="joint_6">
      <hardwareInterface>hardware_interface/PositionJointInterface</hardwareInterface>
    </joint>
  </transmission>
  <!-- ros_control plugin -->
  <gazebo>
    <plugin filename="libgazebo_ros_control.so" name="gazebo_ros_control">
      <robotNamespace>/jaka</robotNamespace>
    </plugin>
  </gazebo>
  <link name="world">
    <origin rpy="0 0 0" xyz="0 0 -0.2"/>
  </link>
  <link name="base">
    <visual>
      <origin rpy="0 0 0" xyz="0 0 0.5"/>
      <geometry>
        <box size="1 2 1"/>
      </geometry>
      <material name="White">
        <color rgba="1.0 1.0 1.0 1.0"/>
      </material>
    </visual>
    <collision>
      <origin rpy="0 0 0" xyz="0 0 0.5"/>
      <geometry>
        <box size="1 2 1"/>
      </geometry>
    </collision>
    <inertial>
      <origin rpy="0.0 0.0 0.0" xyz="0.0 0.0 0.0"/>
      <mass value="10.0"/>
      <inertia ixx="0.001" ixy="0.0" ixz="0.001" iyy="0.0" iyz="0.0" izz="0.001"/>
    </inertial>
  </link>
  <joint name="base_to_world" type="fixed">
    <parent link="world"/>
    <child link="base"/>
    <origin rpy="0.0 0.0 0.0" xyz="0.0 0.0 0.0"/>
  </joint>
  <joint name="fixed_cam" type="fixed">
    <parent link="base"/>
    <child link="cam_base_link"/>
  </joint>
  <joint name="fixed_jaka" type="fixed">
    <parent link="base"/>
    <child link="base_link"/>
  </joint>
</robot>
